Workbook

Sheet task-16
A3: Order ID | B3: Order Date | C3: Customer Name | D3: Product | E3: Category | F3: Region | G3: Quantity | H3: List Price | I3: Discount | J3: Unit Price | K3: Sales | L3: Cost | M3: Profit | N3: Salesperson | O3: Month | P3: Month Number | Q3: Profit Margin %
A4: ORD-1065 | B4: 46114.392 | C4: Nikhil Joshi | D4: Monitor | E4: Electronics | F4: East | G4: 4 | H4: 15000 | I4: 0.1 | J4: 13500 | K4: 54000 | L4: 37739.8 | M4: 16260.2 | N4: Diya | O4: Apr | P4: 4 | Q4: 0.30111481
A5: ORD-1103 | B5: 46116.58 | C5: Komal Shah | D5: Mouse | E5: Accessories | F5: West | G5: 5 | H5: 1200 | I5: 0.15 | J5: 1020 | K5: 5100 | L5: 3541.19 | M5: 1558.81 | N5: Meera | O5: Apr | P5: 4 | Q5: 0.30564902
A6: ORD-1113 | B6: 46118.46 | C6: Jay Joshi | D6: Laptop | E6: Electronics | F6: South | G6: 1 | H6: 55000 | I6: 0.05 | J6: 52250 | K6: 52250 | L6: 37092.49 | M6: 15157.51 | N6: Meera | O6: Apr | P6: 4 | Q6: 0.29009589
A7: ORD-1183 | B7: 46119.46 | C7: Vivek Shah | D7: Desk | E7: Furniture | F7: North | G7: 5 | H7: 12000 | I7: 0.05 | J7: 11400 | K7: 57000 | L7: 36885.94 | M7: 20114.06 | N7: Aarav | O7: Apr | P7: 4 | Q7: 0.35287825
A8: ORD-1112 | B8: 46119.836 | C8: Manav Patel | D8: Backpack | E8: Accessories | F8: South | G8: 4 | H8: 1800 | I8: 0 | J8: 1800 | K8: 7200 | L8: 5705.1 | M8: 1494.9 | N8: Meera | O8: Apr | P8: 4 | Q8: 0.207625
A9: ORD-1096 | B9: 46120.674 | C9: Yash Shah | D9: Keyboard | E9: Accessories | F9: North | G9: 1 | H9: 2200 | I9: 0 | J9: 2200 | K9: 2200 | L9: 1464.19 | M9: 735.81 | N9: Meera | O9: Apr | P9: 4 | Q9: 0.33445909
A10: ORD-1077 | B10: 46120.498 | C10: Meera Shah | D10: Desk | E10: Furniture | F10: South | G10: 2 | H10: 12000 | I10: 0 | J10: 12000 | K10: 24000 | L10: 16905.36 | M10: 7094.64 | N10: Aarav | O10: Apr | P10: 4 | Q10: 0.29561
A11: ORD-1165 | B11: 46121.667 | C11: Rohan Desai | D11: Printer | E11: Electronics | F11: North | G11: 4 | H11: 11000 | I11: 0.15 | J11: 9350 | K11: 37400 | L11: 27459.43 | M11: 9940.57 | N11: Kabir | O11: Apr | P11: 4 | Q11: 0.26579064
A12: ORD-1144 | B12: 46121.703 | C12: Rupal Joshi | D12: Mouse | E12: Accessories | F12: West | G12: 5 | H12: 1200 | I12: 0.05 | J12: 1140 | K12: 5700 | L12: 4553.41 | M12: 1146.59 | N12: Aarav | O12: Apr | P12: 4 | Q12: 0.20115614
A13: ORD-1203 | B13: 46122.62 | C13: Kavya Patel | D13: Printer | E13: Electronics | F13: South | G13: 5 | H13: 11000 | I13: 0.1 | J13: 9900 | K13: 49500 | L13: 33034.32 | M13: 16465.68 | N13: Diya | O13: Apr | P13: 4 | Q13: 0.33264
A14: ORD-1015 | B14: 46123.406 | C14: Smit Mehta | D14: Keyboard | E14: Accessories | F14: North | G14: 5 | H14: 2200 | I14: 0 | J14: 2200 | K14: 11000 | L14: 8101.6 | M14: 2898.4 | N14: Arjun | O14: Apr | P14: 4 | Q14: 0.26349091
A15: ORD-1066 | B15: 46123.47 | C15: Krish Joshi | D15: Backpack | E15: Accessories | F15: West | G15: 1 | H15: 1800 | I15: 0 | J15: 1800 | K15: 1800 | L15: 1426.86 | M15: 373.14 | N15: Riya | O15: Apr | P15: 4 | Q15: 0.2073
... A136: ORD-1109 | B136: 46171.647 | C136: Nirav Desai | D136: Backpack | E136: Accessories | F136: West | G136: 2 | H136: 1800 | I136: 0.1 | J136: 1620 | K136: 3240 | L136: 2439.97 | M136: 800.03 | N136: Arjun | O136: May | P136: 5 | Q136: 0.24692284

Sheet Customer Retention Analysis
A3: Customer | B3: Total Orders | C3: First Purchase Date | D3: Last Purchase Date | E3: Recency Days | F3: Customer Type | H3: Customer Type | I3: Customer Count
A4: Aaradhya Joshi | B4: =COUNTIF('task-16'!$C4:$C136,A4) -> 2 | C4: =_xlfn.MINIFS('task-16'!$B4:$B136,'task-16'!$C4:$C136,A4) -> 46055.403 | D4: =_xlfn.MAXIFS('task-16'!$B4:$B136,'task-16'!$C4:$C136,A4) -> 46095.591 | E4: =INT(MAX('task-16'!$B4:$B136)-D4) -> 76 | F4: =IF(E4>90,"Lost Customer",IF(B4=1,"One-Time Customer","Repeat Customer")) -> Repeat Customer | H4: Repeat Customer | I4: =COUNTIF(F4:F68,H4) -> 34
A5: Aarav Patel | B5: =COUNTIF('task-16'!$C4:$C136,A5) -> 1 | C5: =_xlfn.MINIFS('task-16'!$B4:$B136,'task-16'!$C4:$C136,A5) -> 46107.442 | D5: =_xlfn.MAXIFS('task-16'!$B4:$B136,'task-16'!$C4:$C136,A5) -> 46107.442 | E5: =INT(MAX('task-16'!$B4:$B136)-D5) -> 64 | F5: =IF(E5>90,"Lost Customer",IF(B5=1,"One-Time Customer","Repeat Customer")) -> One-Time Customer | H5: One-Time Customer | I5: =COUNTIF(F4:F68,H5) -> 21
A6: Abhishek Mehta | B6: =COUNTIF('task-16'!$C4:$C136,A6) -> 2 | C6: =_xlfn.MINIFS('task-16'!$B4:$B136,'task-16'!$C4:$C136,A6) -> 46076.74 | D6: =_xlfn.MAXIFS('task-16'!$B4:$B136,'task-16'!$C4:$C136,A6) -> 46136.397 | E6: =INT(MAX('task-16'!$B4:$B136)-D6) -> 35 | F6: =IF(E6>90,"Lost Customer",IF(B6=1,"One-Time Customer","Repeat Customer")) -> Repeat Customer | H6: Lost Customer | I6: =COUNTIF(F4:F68,H6) -> 10
A7: Aditi Joshi | B7: =COUNTIF('task-16'!$C4:$C136,A7) -> 1 | C7: =_xlfn.MINIFS('task-16'!$B4:$B136,'task-16'!$C4:$C136,A7) -> 46038.526 | D7: =_xlfn.MAXIFS('task-16'!$B4:$B136,'task-16'!$C4:$C136,A7) -> 46038.526 | E7: =INT(MAX('task-16'!$B4:$B136)-D7) -> 133 | F7: =IF(E7>90,"Lost Customer",IF(B7=1,"One-Time Customer","Repeat Customer")) -> Lost Customer | H7: Total Customers | I7: =SUM(I4:I6) -> 65
A8: Akash Patel | B8: =COUNTIF('task-16'!$C4:$C136,A8) -> 2 | C8: =_xlfn.MINIFS('task-16'!$B4:$B136,'task-16'!$C4:$C136,A8) -> 46076.809 | D8: =_xlfn.MAXIFS('task-16'!$B4:$B136,'task-16'!$C4:$C136,A8) -> 46130.676 | E8: =INT(MAX('task-16'!$B4:$B136)-D8) -> 41 | F8: =IF(E8>90,"Lost Customer",IF(B8=1,"One-Time Customer","Repeat Customer")) -> Repeat Customer | H8: Retention Rate % | I8: =IF(I7=0,0,I4/I7) -> 0.52307692
A9: Amit Patel | B9: =COUNTIF('task-16'!$C4:$C136,A9) -> 1 | C9: =_xlfn.MINIFS('task-16'!$B4:$B136,'task-16'!$C4:$C136,A9) -> 46133.738 | D9: =_xlfn.MAXIFS('task-16'!$B4:$B136,'task-16'!$C4:$C136,A9) -> 46133.738 | E9: =INT(MAX('task-16'!$B4:$B136)-D9) -> 38 | F9: =IF(E9>90,"Lost Customer",IF(B9=1,"One-Time Customer","Repeat Customer")) -> One-Time Customer
A10: Anjali Desai | B10: =COUNTIF('task-16'!$C4:$C136,A10) -> 3 | C10: =_xlfn.MINIFS('task-16'!$B4:$B136,'task-16'!$C4:$C136,A10) -> 46031.501 | D10: =_xlfn.MAXIFS('task-16'!$B4:$B136,'task-16'!$C4:$C136,A10) -> 46081.566 | E10: =INT(MAX('task-16'!$B4:$B136)-D10) -> 90 | F10: =IF(E10>90,"Lost Customer",IF(B10=1,"One-Time Customer","Repeat Customer")) -> Repeat Customer
A11: Ankit Mehta | B11: =COUNTIF('task-16'!$C4:$C136,A11) -> 3 | C11: =_xlfn.MINIFS('task-16'!$B4:$B136,'task-16'!$C4:$C136,A11) -> 46056.624 | D11: =_xlfn.MAXIFS('task-16'!$B4:$B136,'task-16'!$C4:$C136,A11) -> 46146.76 | E11: =INT(MAX('task-16'!$B4:$B136)-D11) -> 25 | F11: =IF(E11>90,"Lost Customer",IF(B11=1,"One-Time Customer","Repeat Customer")) -> Repeat Customer
A12: Arjun Mehta | B12: =COUNTIF('task-16'!$C4:$C136,A12) -> 1 | C12: =_xlfn.MINIFS('task-16'!$B4:$B136,'task-16'!$C4:$C136,A12) -> 46040.662 | D12: =_xlfn.MAXIFS('task-16'!$B4:$B136,'task-16'!$C4:$C136,A12) -> 46040.662 | E12: =INT(MAX('task-16'!$B4:$B136)-D12) -> 131 | F12: =IF(E12>90,"Lost Customer",IF(B12=1,"One-Time Customer","Repeat Customer")) -> Lost Customer
A13: Bhavin Desai | B13: =COUNTIF('task-16'!$C4:$C136,A13) -> 2 | C13: =_xlfn.MINIFS('task-16'!$B4:$B136,'task-16'!$C4:$C136,A13) -> 46102.807 | D13: =_xlfn.MAXIFS('task-16'!$B4:$B136,'task-16'!$C4:$C136,A13) -> 46159.633 | E13: =INT(MAX('task-16'!$B4:$B136)-D13) -> 12 | F13: =IF(E13>90,"Lost Customer",IF(B13=1,"One-Time Customer","Repeat Customer")) -> Repeat Customer
A14: Bhavya Shah | B14: =COUNTIF('task-16'!$C4:$C136,A14) -> 1 | C14: =_xlfn.MINIFS('task-16'!$B4:$B136,'task-16'!$C4:$C136,A14) -> 46051.52 | D14: =_xlfn.MAXIFS('task-16'!$B4:$B136,'task-16'!$C4:$C136,A14) -> 46051.52 | E14: =INT(MAX('task-16'!$B4:$B136)-D14) -> 120 | F14: =IF(E14>90,"Lost Customer",IF(B14=1,"One-Time Customer","Repeat Customer")) -> Lost Customer
A15: Chirag Mehta | B15: =COUNTIF('task-16'!$C4:$C136,A15) -> 2 | C15: =_xlfn.MINIFS('task-16'!$B4:$B136,'task-16'!$C4:$C136,A15) -> 46025.604 | D15: =_xlfn.MAXIFS('task-16'!$B4:$B136,'task-16'!$C4:$C136,A15) -> 46150.647 | E15: =INT(MAX('task-16'!$B4:$B136)-D15) -> 21 | F15: =IF(E15>90,"Lost Customer",IF(B15=1,"One-Time Customer","Repeat Customer")) -> Repeat Customer
A16: Darsh Shah | B16: =COUNTIF('task-16'!$C4:$C136,A16) -> 2 | C16: =_xlfn.MINIFS('task-16'!$B4:$B136,'task-16'!$C4:$C136,A16) -> 46072.774 | D16: =_xlfn.MAXIFS('task-16'!$B4:$B136,'task-16'!$C4:$C136,A16) -> 46132.769 | E16: =INT(MAX('task-16'!$B4:$B136)-D16) -> 39 | F16: =IF(E16>90,"Lost Customer",IF(B16=1,"One-Time Customer","Repeat Customer")) -> Repeat Customer
A17: Darshil Desai | B17: =COUNTIF('task-16'!$C4:$C136,A17) -> 2 | C17: =_xlfn.MINIFS('task-16'!$B4:$B136,'task-16'!$C4:$C136,A17) -> 46081.351 | D17: =_xlfn.MAXIFS('task-16'!$B4:$B136,'task-16'!$C4:$C136,A17) -> 46083.49 | E17: =INT(MAX('task-16'!$B4:$B136)-D17) -> 88 | F17: =IF(E17>90,"Lost Customer",IF(B17=1,"One-Time Customer","Repeat Customer")) -> Repeat Customer
A18: Diya Patel | B18: =COUNTIF('task-16'!$C4:$C136,A18) -> 1 | C18: =_xlfn.MINIFS('task-16'!$B4:$B136,'task-16'!$C4:$C136,A18) -> 46153.695 | D18: =_xlfn.MAXIFS('task-16'!$B4:$B136,'task-16'!$C4:$C136,A18) -> 46153.695 | E18: =INT(MAX('task-16'!$B4:$B136)-D18) -> 18 | F18: =IF(E18>90,"Lost Customer",IF(B18=1,"One-Time Customer","Repeat Customer")) -> One-Time Customer
A19: Hardik Patel | B19: =COUNTIF('task-16'!$C4:$C136,A19) -> 2 | C19: =_xlfn.MINIFS('task-16'!$B4:$B136,'task-16'!$C4:$C136,A19) -> 46038.367 | D19: =_xlfn.MAXIFS('task-16'!$B4:$B136,'task-16'!$C4:$C136,A19) -> 46077.621 | E19: =INT(MAX('task-16'!$B4:$B136)-D19) -> 94 | F19: =IF(E19>90,"Lost Customer",IF(B19=1,"One-Time Customer","Repeat Customer")) -> Lost Customer
A20: Heena Joshi | B20: =COUNTIF('task-16'!$C4:$C136,A20) -> 1 | C20: =_xlfn.MINIFS('task-16'!$B4:$B136,'task-16'!$C4:$C136,A20) -> 46097.548 | D20: =_xlfn.MAXIFS('task-16'!$B4:$B136,'task-16'!$C4:$C136,A20) -> 46097.548 | E20: =INT(MAX('task-16'!$B4:$B136)-D20) -> 74 | F20: =IF(E20>90,"Lost Customer",IF(B20=1,"One-Time Customer","Repeat Customer")) -> One-Time Customer
A21: Hetal Shah | B21: =COUNTIF('task-16'!$C4:$C136,A21) -> 1 | C21: =_xlfn.MINIFS('task-16'!$B4:$B136,'task-16'!$C4:$C136,A21) -> 46169.785 | D21: =_xlfn.MAXIFS('task-16'!$B4:$B136,'task-16'!$C4:$C136,A21) -> 46169.785 | E21: =INT(MAX('task-16'!$B4:$B136)-D21) -> 2 | F21: =IF(E21>90,"Lost Customer",IF(B21=1,"One-Time Customer","Repeat Customer")) -> One-Time Customer
A22: Isha Joshi | B22: =COUNTIF('task-16'!$C4:$C136,A22) -> 2 | C22: =_xlfn.MINIFS('task-16'!$B4:$B136,'task-16'!$C4:$C136,A22) -> 46066.644 | D22: =_xlfn.MAXIFS('task-16'!$B4:$B136,'task-16'!$C4:$C136,A22) -> 46105.779 | E22: =INT(MAX('task-16'!$B4:$B136)-D22) -> 66 | F22: =IF(E22>90,"Lost Customer",IF(B22=1,"One-Time Customer","Repeat Customer")) -> Repeat Customer
A23: Jatin Desai | B23: =COUNTIF('task-16'!$C4:$C136,A23) -> 2 | C23: =_xlfn.MINIFS('task-16'!$B4:$B136,'task-16'!$C4:$C136,A23) -> 46078.819 | D23: =_xlfn.MAXIFS('task-16'!$B4:$B136,'task-16'!$C4:$C136,A23) -> 46112.73 | E23: =INT(MAX('task-16'!$B4:$B136)-D23) -> 59 | F23: =IF(E23>90,"Lost Customer",IF(B23=1,"One-Time Customer","Repeat Customer")) -> Repeat Customer
A24: Jay Joshi | B24: =COUNTIF('task-16'!$C4:$C136,A24) -> 6 | C24: =_xlfn.MINIFS('task-16'!$B4:$B136,'task-16'!$C4:$C136,A24) -> 46042.652 | D24: =_xlfn.MAXIFS('task-16'!$B4:$B136,'task-16'!$C4:$C136,A24) -> 46167.371 | E24: =INT(MAX('task-16'!$B4:$B136)-D24) -> 4 | F24: =IF(E24>90,"Lost Customer",IF(B24=1,"One-Time Customer","Repeat Customer")) -> Repeat Customer
A25: Jaydeep Mehta | B25: =COUNTIF('task-16'!$C4:$C136,A25) -> 1 | C25: =_xlfn.MINIFS('task-16'!$B4:$B136,'task-16'!$C4:$C136,A25) -> 46170.835 | D25: =_xlfn.MAXIFS('task-16'!$B4:$B136,'task-16'!$C4:$C136,A25) -> 46170.835 | E25: =INT(MAX('task-16'!$B4:$B136)-D25) -> 0 | F25: =IF(E25>90,"Lost Customer",IF(B25=1,"One-Time Customer","Repeat Customer")) -> One-Time Customer
A26: Jinal Desai | B26: =COUNTIF('task-16'!$C4:$C136,A26) -> 3 | C26: =_xlfn.MINIFS('task-16'!$B4:$B136,'task-16'!$C4:$C136,A26) -> 46046.6 | D26: =_xlfn.MAXIFS('task-16'!$B4:$B136,'task-16'!$C4:$C136,A26) -> 46164.447 | E26: =INT(MAX('task-16'!$B4:$B136)-D26) -> 7 | F26: =IF(E26>90,"Lost Customer",IF(B26=1,"One-Time Customer","Repeat Customer")) -> Repeat Customer
A27: Karan Desai | B27: =COUNTIF('task-16'!$C4:$C136,A27) -> 2 | C27: =_xlfn.MINIFS('task-16'!$B4:$B136,'task-16'!$C4:$C136,A27) -> 46078.708 | D27: =_xlfn.MAXIFS('task-16'!$B4:$B136,'task-16'!$C4:$C136,A27) -> 46148.756 | E27: =INT(MAX('task-16'!$B4:$B136)-D27) -> 23 | F27: =IF(E27>90,"Lost Customer",IF(B27=1,"One-Time Customer","Repeat Customer")) -> Repeat Customer
A28: Kavya Patel | B28: =COUNTIF('task-16'!$C4:$C136,A28) -> 3 | C28: =_xlfn.MINIFS('task-16'!$B4:$B136,'task-16'!$C4:$C136,A28) -> 46043.771 | D28: =_xlfn.MAXIFS('task-16'!$B4:$B136,'task-16'!$C4:$C136,A28) -> 46138.511 | E28: =INT(MAX('task-16'!$B4:$B136)-D28) -> 33 | F28: =IF(E28>90,"Lost Customer",IF(B28=1,"One-Time Customer","Repeat Customer")) -> Repeat Customer | H28: Key Business Insights
A29: Khushi Mehta | B29: =COUNTIF('task-16'!$C4:$C136,A29) -> 1 | C29: =_xlfn.MINIFS('task-16'!$B4:$B136,'task-16'!$C4:$C136,A29) -> 46070.66 | D29: =_xlfn.MAXIFS('task-16'!$B4:$B136,'task-16'!$C4:$C136,A29) -> 46070.66 | E29: =INT(MAX('task-16'!$B4:$B136)-D29) -> 101 | F29: =IF(E29>90,"Lost Customer",IF(B29=1,"One-Time Customer","Repeat Customer")) -> Lost Customer
A30: Komal Shah | B30: =COUNTIF('task-16'!$C4:$C136,A30) -> 4 | C30: =_xlfn.MINIFS('task-16'!$B4:$B136,'task-16'!$C4:$C136,A30) -> 46088.734 | D30: =_xlfn.MAXIFS('task-16'!$B4:$B136,'task-16'!$C4:$C136,A30) -> 46168.721 | E30: =INT(MAX('task-16'!$B4:$B136)-D30) -> 3 | F30: =IF(E30>90,"Lost Customer",IF(B30=1,"One-Time Customer","Repeat Customer")) -> Repeat Customer | H30: 1. 52.31% of customers are repeat customers, indicating that more than half of the customer base has made multiple purchases.
A31: Krish Joshi | B31: =COUNTIF('task-16'!$C4:$C136,A31) -> 1 | C31: =_xlfn.MINIFS('task-16'!$B4:$B136,'task-16'!$C4:$C136,A31) -> 46123.47 | D31: =_xlfn.MAXIFS('task-16'!$B4:$B136,'task-16'!$C4:$C136,A31) -> 46123.47 | E31: =INT(MAX('task-16'!$B4:$B136)-D31) -> 48 | F31: =IF(E31>90,"Lost Customer",IF(B31=1,"One-Time Customer","Repeat Customer")) -> One-Time Customer | H31: 2. 32.31% are one-time customers, representing an opportunity for repeat-purchase campaigns.
A32: Krupa Shah | B32: =COUNTIF('task-16'!$C4:$C136,A32) -> 1 | C32: =_xlfn.MINIFS('task-16'!$B4:$B136,'task-16'!$C4:$C136,A32) -> 46105.471 | D32: =_xlfn.MAXIFS('task-16'!$B4:$B136,'task-16'!$C4:$C136,A32) -> 46105.471 | E32: =INT(MAX('task-16'!$B4:$B136)-D32) -> 66 | F32: =IF(E32>90,"Lost Customer",IF(B32=1,"One-Time Customer","Repeat Customer")) -> One-Time Customer | H32: 3. 15.38% are classified as lost customers, requiring re-engagement strategies.
A33: Kunal Mehta | B33: =COUNTIF('task-16'!$C4:$C136,A33) -> 2 | C33: =_xlfn.MINIFS('task-16'!$B4:$B136,'task-16'!$C4:$C136,A33) -> 46050.475 | D33: =_xlfn.MAXIFS('task-16'!$B4:$B136,'task-16'!$C4:$C136,A33) -> 46088.667 | E33: =INT(MAX('task-16'!$B4:$B136)-D33) -> 83 | F33: =IF(E33>90,"Lost Customer",IF(B33=1,"One-Time Customer","Repeat Customer")) -> Repeat Customer | H33: 4. The business should focus on converting one-time customers into repeat customers and reactivating lost customers.
A34: Manav Patel | B34: =COUNTIF('task-16'!$C4:$C136,A34) -> 4 | C34: =_xlfn.MINIFS('task-16'!$B4:$B136,'task-16'!$C4:$C136,A34) -> 46057.623 | D34: =_xlfn.MAXIFS('task-16'!$B4:$B136,'task-16'!$C4:$C136,A34) -> 46125.458 | E34: =INT(MAX('task-16'!$B4:$B136)-D34) -> 46 | F34: =IF(E34>90,"Lost Customer",IF(B34=1,"One-Time Customer","Repeat Customer")) -> Repeat Customer
A35: Mansi Patel | B35: =COUNTIF('task-16'!$C4:$C136,A35) -> 1 | C35: =_xlfn.MINIFS('task-16'!$B4:$B136,'task-16'!$C4:$C136,A35) -> 46025.797 | D35: =_xlfn.MAXIFS('task-16'!$B4:$B136,'task-16'!$C4:$C136,A35) -> 46025.797 | E35: =INT(MAX('task-16'!$B4:$B136)-D35) -> 145 | F35: =IF(E35>90,"Lost Customer",IF(B35=1,"One-Time Customer","Repeat Customer")) -> Lost Customer
A36: Maulik Patel | B36: =COUNTIF('task-16'!$C4:$C136,A36) -> 1 | C36: =_xlfn.MINIFS('task-16'!$B4:$B136,'task-16'!$C4:$C136,A36) -> 46093.542 | D36: =_xlfn.MAXIFS('task-16'!$B4:$B136,'task-16'!$C4:$C136,A36) -> 46093.542 | E36: =INT(MAX('task-16'!$B4:$B136)-D36) -> 78 | F36: =IF(E36>90,"Lost Customer",IF(B36=1,"One-Time Customer","Repeat Customer")) -> One-Time Customer
A37: Meera Shah | B37: =COUNTIF('task-16'!$C4:$C136,A37) -> 5 | C37: =_xlfn.MINIFS('task-16'!$B4:$B136,'task-16'!$C4:$C136,A37) -> 46082.86 | D37: =_xlfn.MAXIFS('task-16'!$B4:$B136,'task-16'!$C4:$C136,A37) -> 46157.647 | E37: =INT(MAX('task-16'!$B4:$B136)-D37) -> 14 | F37: =IF(E37>90,"Lost Customer",IF(B37=1,"One-Time Customer","Repeat Customer")) -> Repeat Customer
A38: Meet Desai | B38: =COUNTIF('task-16'!$C4:$C136,A38) -> 3 | C38: =_xlfn.MINIFS('task-16'!$B4:$B136,'task-16'!$C4:$C136,A38) -> 46077.8 | D38: =_xlfn.MAXIFS('task-16'!$B4:$B136,'task-16'!$C4:$C136,A38) -> 46100.667 | E38: =INT(MAX('task-16'!$B4:$B136)-D38) -> 71 | F38: =IF(E38>90,"Lost Customer",IF(B38=1,"One-Time Customer","Repeat Customer")) -> Repeat Customer
A39: Mihir Patel | B39: =COUNTIF('task-16'!$C4:$C136,A39) -> 1 | C39: =_xlfn.MINIFS('task-16'!$B4:$B136,'task-16'!$C4:$C136,A39) -> 46160.506 | D39: =_xlfn.MAXIFS('task-16'!$B4:$B136,'task-16'!$C4:$C136,A39) -> 46160.506 | E39: =INT(MAX('task-16'!$B4:$B136)-D39) -> 11 | F39: =IF(E39>90,"Lost Customer",IF(B39=1,"One-Time Customer","Repeat Customer")) -> One-Time Customer
A40: Mitali Shah | B40: =COUNTIF('task-16'!$C4:$C136,A40) -> 2 | C40: =_xlfn.MINIFS('task-16'!$B4:$B136,'task-16'!$C4:$C136,A40) -> 46135.768 | D40: =_xlfn.MAXIFS('task-16'!$B4:$B136,'task-16'!$C4:$C136,A40) -> 46161.825 | E40: =INT(MAX('task-16'!$B4:$B136)-D40) -> 9 | F40: =IF(E40>90,"Lost Customer",IF(B40=1,"One-Time Customer","Repeat Customer")) -> Repeat Customer
A41: Nandini Shah | B41: =COUNTIF('task-16'!$C4:$C136,A41) -> 2 | C41: =_xlfn.MINIFS('task-16'!$B4:$B136,'task-16'!$C4:$C136,A41) -> 46072.478 | D41: =_xlfn.MAXIFS('task-16'!$B4:$B136,'task-16'!$C4:$C136,A41) -> 46171.526 | E41: =INT(MAX('task-16'!$B4:$B136)-D41) -> 0 | F41: =IF(E41>90,"Lost Customer",IF(B41=1,"One-Time Customer","Repeat Customer")) -> Repeat Customer
A42: Neha Shah | B42: =COUNTIF('task-16'!$C4:$C136,A42) -> 2 | C42: =_xlfn.MINIFS('task-16'!$B4:$B136,'task-16'!$C4:$C136,A42) -> 46053.395 | D42: =_xlfn.MAXIFS('task-16'!$B4:$B136,'task-16'!$C4:$C136,A42) -> 46107.651 | E42: =INT(MAX('task-16'!$B4:$B136)-D42) -> 64 | F42: =IF(E42>90,"Lost Customer",IF(B42=1,"One-Time Customer","Repeat Customer")) -> Repeat Customer
...
